Workbook

Sheet Agenda Draft 01
A1: Day | B1: Time | C1: Topic | D1: Presenter | E1: Key Content
A2: 1 | C2: Opening & Objectives | D2: Mr. Saleh & Sameh Khalil | E2: • Purpose of meeting • 2030 ambition • What limits growth • Need for new verticals • Growth mindset • Brainstorming rules & scoring model intro.
C3: Brainstorming Method & Framework | D3: Dr Samy Katar | E3: • Opportunity Scoring Model • Brainstorming rules • How to think about opportunities (Data-based logic) • Simple scoring model intro
C5: Wound Care Business | D5: Mahmoud Younis | E5: • Vision 2030 • Market • Growth drivers • Portfolio • Top opportunities • Competition • Risks • Support needed
C6: Tender Analysis and Dialysis business | D6: Weal Korashi | E6: Same structure as above
C7: Classic Business | D7: BU Manager | E7: Same structure as above
C8: Cardiology Business | D8: Ayman Kaddah | E8: Same structure as above
C9: Equipment Business | D9: BU Manager | E9: Same structure as above
C10: Open Brainstorming Session # Day 1 | D10: All | E10: • Cross-BU synergies • What Worked / Didn’t • Enablers (Role, Responsibility, Timeline, Review Freqancy • Action Planning (12–18–24 Months) • Cross-Functional Priorities
C11: Open Brainstorming Session # Day 2 | D11: All | E11: Same structure as above
C12: Open Brainstorming Session # Day 3 | D12: All | E12: Same structure as above
C13: 2030 Final Alignment Discussion | D13: CEO + All | E13: • Summary • Alignment • Next steps
A14: 3 | C14: Operations Enabler Update | D14: Faizan Rao | E14: • Effectivnes of Change. • Next Step (Ops support to sales) • Inventory visibility • MRP Demo • KPI Review (OTIF, A3 Report, Dashboard). • Budget 2026

Sheet Title
A1: <<2026>> Year of Excellence (YoE) YoE 4 1b Y 05

Sheet Agenda V01
B1: Year of Excellence ~ Journey to 1 Billion
B2: Offsite Strategy Meeting - Egypt 2025
B4: Time | C4: Subject | D4: Presenter | E4: Key Content
B5: Day 01 (07 Dec, 2025)
B6: 9:00 – 9:30 | C6: Opening & Objectives | D6: Mr. Saleh & Dr. Sameh | E6: • Purpose of Egypt strategy meeting • 2030 ambition • Expectations from each BU • Why new verticals matter • How this meeting will run • Importance of alignment
B7: 9:30 – 10:00 | C7: Brainstorming Methodology | D7: Dr. Sameh | E7: • Opportunity Scoring Model (OSM) • Brainstorming rules • How to think about opportunities (Data-based logic) • Simple scoring model intro
B8: 10:00 – 11:00 | C8: Wound Care / Diabetes / Rehabilitation / Tenders | D8: Mahmoud Younis | E8: • Market opportunities • Current Pipeline • Partner opportunities • High-potential SKUs & High Value Tender Timelines • Required support • Competition analysis • Historical challenges in tender pricing • Key wins/losses • Market gaps
B9: 11:00 – 11:30 | C9: Break
B10: 11:30 – 13:30 | C10: Dialysis Business | D10: Wael Korashi | E10: • Market opportunities • Current Pipeline • Partner opportunities • High-potential SKUs & High Value Tender Timelines • Required support • Competition analysis • Historical challenges in tender pricing • Key wins/losses • Market gaps
B11: 13:30 – 14:30 | C11: Lunch + Prayer Break
B12: 14:30 – 17:30 | C12: Open Discussion & Brainstorming Day-01 | D12: All | E12: • Day Summary (Idea collection) • What opportunities can be combined? • Review OSM
B15: Day 02 (08 Dec, 2025)
B16: 9:00 – 11:00 | C16: Classic Business | D16: Mohamed Samir | E16: • Market opportunities • Current Pipeline • Partner opportunities • High-potential SKUs & High Value Tender Timelines • Required support • Competition analysis • Historical challenges in tender pricing • Key wins/losses • Market gaps
B17: 11:00 – 11:30 | C17: Break
B18: 11:30 – 13:00 | C18: Cardiology Business | D18: Ayman Kaddah | E18: • Market opportunities • Current Pipeline • Partner opportunities • Tender readiness (High Value) • High-potential SKUs • Required support • Competition analysis • Historical challenges in tender pricing • Key wins/losses • Market gaps
B19: 13:30 – 14:30 | C19: Lunch + Prayer Break
B20: 15:30 – 17:00 | C20: Open Discussion & Brainstorming Day-02 | D20: All | E20: • Day Summary (Idea collection) • What opportunities can be combined? • Review OSM
B22: Day 03 (09 Dec, 2025)
B23: 9:00 – 11:00 | C23: Equipment Business | D23: Ahmad Awad | E23: • Market opportunities • Current Pipeline • Partner opportunities • Tender readiness (High Value) • High-potential SKUs • Required support • Competition analysis • Historical challenges in tender pricing • Key wins/losses • Market gaps • Post-sales requirements
B24: 11:00 – 11:30 | C24: Break
B25: 11:30 – 13:30 | C25: Open Discussion & Brainstorming Day-03 | D25: All | E25: • Day Summary (Idea collection) • What opportunities can be combined? • Review OSM
B26: 13:30 – 14:30 | C26: Lunch + Prayer Break
B27: 14:30 – 15:30 | C27: Ops 4 Months Performance Review and Next Step | D27: Faizan Rao | E27: • Performance Reivew and Sales Feedback. • Next Year Operational Calander & SOP. • OTIF & A3 Report & DashBoard. • MRP v1 Demo & MRP v2 timeline. • Inventory Classification (ABC/XYZ). • Inventory Review Meeting (Monthly). • Inventory 2026 Action Plan. • Supplier follow-up system. • NUPCO changing tracking. • NUPCO portal changes MGMT.
B28: 15:30 – 17:30 | C28: 2030 Final Alignment Discussion | D28: All | E28: • Finalize opportunity shortlist • Assign owners • Prepare input for action plan
B29: 18:30 – XX:XX | C29: Dinner @ Khan Khalili

Sheet WS
F3: SBU
F4: Classic
F5: Wound-Care
F6: Equipments
F7: Cardiology
F8: Dialysis
F9: Surgical Inst.
B19: Thing to Ask
B21: Critical Drop Zone
B22: Regulatory | C22: Complex
B23: Tender feasibility | C23: Low
B24: Product complexity | C24: Very difficult
B25: Supplier availability | C25: Very Low
B26: Entry barriers | C26: Very High
B29: Category | C29: Weight | D29: Field
B30: Market Attractiveness | C30: 0.4 | D30: Y01 Revenues, 5Y CAGR, Margin, Market Awareness
B31: Ease of Entry | C31: 0.3 | D31: Product, Operational, BD, Regulatory, Tender
B32: Strategic Fit | C32: 0.2 | D32: Localization potential, JMI capabilities
B33: Risk | C33: 0.1 | D33: Entry barriers, complexity
B36: Weight
B37: Market Awareness & Capability
B38: Rating | C38: Score | D38: Weight | E38: Description
B39: Yes – Very High | C39: 5 | D39: 0.05 | E39: Market fully understands the product
B40: Yes – High | C40: 4 | D40: 0.05 | E40: Good awareness; some education needed
B41: Partial | C41: 3 | D41: 0.05 | E41: Mixed understanding; requires effort
B42: Low Awareness | C42: 2 | D42: 0.05 | E42: Limited knowledge in market
B43: No – Minimal | C43: 1 | D43: 0.05 | E43: No awareness; heavy education needed
B44: To Be Assessed | C44: 0 | D44: 0.05 | E44: Information not available
B47: Field Name | C47: Weight
B48: Market Awareness & Capability | C48: 0.05
B49: Entry Barriers | C49: 0.05
B50: Supplier Availability / Partnership Readiness | C50: 0.05
B51: Gross Margin Potential | C51: 0.1
B52: Ease of Entry – Tender Feasibility (NUPCO likelihood) | C52: 0.05
B53: Ease of Entry – Private Market | C53: 0.05
B54: Ease of Entry – Business Development | C54: 0.05
B55: Ease of Entry – Regulatory | C55: 0.05
B56: Ease of Entry – Product Complexity | C56: 0.1
B57: Ease of Entry – Operational Complexity | C57: 0.1
B58: Localization Opportunities | C58: 0.1
...

Sheet Opportunity Scoring Model
I2: Market | W2: Financial | AK2: Ease of Entry | BM2: Market | CA2: Financial | CO2: Ease of Entry
C4: # | E4: SBU | G4: Business Segment | I4: Opportunity | K4: Awareness & Capability | M4: Entry Barriers | Q4: Strategic Fit With JMI Portfolio | S4: Commercial Readiness | U4: Sales Force Readiness | W4: Total Market Size (in SAR Millions) | Y4: JMI Target & Growth (In SAR Millions) | AE4: Gross Margin Potential | AG4: Export Potential | AI4: Capital Requirement (in SAR Millions) | AK4: Tender Feasibility (NUPCO likelihood) | AM4: Private Market | AO4: Business Development | AQ4: Regulatory Complexity | AS4: Product Complexity | AU4: Operational Complexity | AW4: Localization Opportunities | AY4: Time To Market | BA4: Check | BC4: Score | BM4: Opportunity | BO4: Awareness & Capability | BQ4: Entry Barriers | BU4: Strategic Fit With JMI Portfolio | BW4: Commercial Readiness | BY4: Sales Force Readiness | CA4: Total Market Size (in SAR Millions) | CC4: JMI Target & Growth (In SAR Millions) | CI4: Gross Margin Potential | CK4: Export Potential | CM4: Capital Requirement | CO4: Tender Feasibility (NUPCO likelihood) | CQ4: Private Market | CS4: Business Development | CU4: Regulatory Complexity | CW4: Product Complexity | CY4: Operational Complexity | DA4: Localization Opportunities | DC4: Time To Market
M6: Remarks | Y6: Y01 | AA6: CAGR | AC6: T-Y05 | BM6: =VLOOKUP(BM4,'OSM Field'!$C$4:$E$26,3,0) -> 0 | BO6: =VLOOKUP(BO4,'OSM Field'!$C$4:$E$26,3,0) -> 0.05 | BQ6: Remarks | BS6: =VLOOKUP(BQ4,'OSM Field'!$C$4:$E$26,3,0) -> 0.05 | BU6: =VLOOKUP(BU4,'OSM Field'!$C$4:$E$26,3,0) -> 0.07 | BW6: =VLOOKUP(BW4,'OSM Field'!$C$4:$E$26,3,0) -> 0.05 | BY6: =VLOOKUP(BY4,'OSM Field'!$C$4:$E$26,3,0) -> 0.07 | CA6: =VLOOKUP(CA4,'OSM Field'!$C$4:$E$26,3,0) -> 0 | CC6: ='OSM Field'!E13 -> 0.1 | CE6: ='OSM Field'!E14 -> 0.08 | CG6: ='OSM Field'!E15 -> 0.1 | CI6: =VLOOKUP(CI4,'OSM Field'!$C$4:$E$26,3,0) -> 0.1 | CK6: =VLOOKUP(CK4,'OSM Field'!$C$4:$E$26,3,0) -> 0.04 | CM6: =VLOOKUP(CM4,'OSM Field'!$C$4:$E$26,3,0) -> 0 | CO6: =VLOOKUP(CO4,'OSM Field'!$C$4:$E$26,3,0) -> 0.07 | CQ6: =VLOOKUP(CQ4,'OSM Field'!$C$4:$E$26,3,0) -> 0.05 | CS6: =VLOOKUP(CS4,'OSM Field'!$C$4:$E$26,3,0) -> 0.05 | CU6: =VLOOKUP(CU4,'OSM Field'!$C$4:$E$26,3,0) -> 0.05 | CW6: =VLOOKUP(CW4,'OSM Field'!$C$4:$E$26,3,0) -> 0.07 | CY6: =VLOOKUP(CY4,'OSM Field'!$C$4:$E$26,3,0) -> 0.05 | DA6: =VLOOKUP(DA4,'OSM Field'!$C$4:$E$26,3,0) -> 0 | DC6: =VLOOKUP(DC4,'OSM Field'!$C$4:$E$26,3,0) -> 0.05
C8: 1 | E8: Surgical Inst. | G8: Surgical instruments | I8: High | K8: High | M8: Proper supplier | O8: Medium Barriers | Q8: Strong Fit | S8: Partially Ready | U8: Minor Additions | W8: 100 | Y8: 4 | AA8: 0.15 | AC8: =ROUND(Y8*(1+AA8)^5,0) -> 8 | AE8: High | AG8: Minimal | AI8: 0 | AK8: High | AM8: Difficult | AO8: Easy | AQ8: Easy | AS8: Moderate | AU8: Moderate | AW8: Minimal | AY8: Medium | BA8: =IF(COUNTA(AY8,AW8,AU8,AS8,AQ8,AO8,AM8,AK8,AI8,AG8,AE8,AC8,AA8,Y8,W8,U8,S8,Q8,O8,K8,I8)=21,"✓","✗") -> ✓ | BC8: =IFERROR(SUM(BM8:DC8),"") -> 3.17 | BE8: =IFERROR(LOOKUP(BC8,'OSM - Rating and Score'!$G$103:$I$108,'OSM - Rating and Score'!$C$103:$C$108),"") -> Moderate | BM8: =ROUND(VLOOKUP(I8,'OSM - Rating and Score'!$C$8:$D$13,2,0)*BM$6,2) -> 0 | BO8: =ROUND(VLOOKUP(K8,'OSM - Rating and Score'!$C$8:$D$13,2,0)*BO$6,2) -> 0.2 | BS8: =ROUND(VLOOKUP(O8,'OSM - Rating and Score'!$C$17:$D$22,2,0)*BS$6,2) -> 0.15 | BU8: =ROUND(VLOOKUP(Q8,'OSM - Rating and Score'!$C$56:$D$61,2,0)*BU$6,2) -> 0.28 | BW8: =ROUND(VLOOKUP(S8,'OSM - Rating and Score'!$C$26:$D$31,2,0)*BW$6,2) -> 0.15 | BY8: =ROUND(VLOOKUP(U8,'OSM - Rating and Score'!$C$35:$D$40,2,0)*BY$6,2) -> 0.28 | CC8: =ROUND(LOOKUP(Y8,'OSM - Rating and Score'!$G$85:$I$90,'OSM - Rating and Score'!$D$85:$D$90)*CC$6,2) -> 0.2 | CE8: =ROUND(LOOKUP(AA8,'OSM - Rating and Score'!$G$113:$I$118,'OSM - Rating and Score'!$D$113:$D$118)*CE$6,2) -> 0.08 | CG8: =ROUND(LOOKUP(AC8,'OSM - Rating and Score'!$G$94:$I$99,'OSM - Rating and Score'!$D$85:$D$90)*CG$6,2) -> 0.1 | CI8: =ROUND(VLOOKUP(AE8,'OSM - Rating and Score'!$C$8:$D$13,2,0)*CI$6,2) -> 0.4 | CK8: =ROUND(VLOOKUP(AG8,'OSM - Rating and Score'!$C$8:$D$13,2,0)*CK$6,2) -> 0.04 | CM8: 0 | CO8: =ROUND(VLOOKUP(AK8,'OSM - Rating and Score'!$C$8:$D$13,2,0)*CO$6,2) -> 0.28 | CQ8: =ROUND(VLOOKUP(AM8,'OSM - Rating and Score'!$C$47:$D$52,2,0)*CQ$6,2) -> 0.1 | CS8: =ROUND(VLOOKUP(AO8,'OSM - Rating and Score'!$C$47:$D$52,2,0)*CS$6,2) -> 0.2 | CU8: =ROUND(VLOOKUP(AQ8,'OSM - Rating and Score'!$C$47:$D$52,2,0)*CU$6,2) -> 0.2 | CW8: =ROUND(VLOOKUP(AS8,'OSM - Rating and Score'!$C$47:$D$52,2,0)*CW$6,2) -> 0.21 | CY8: =ROUND(VLOOKUP(AU8,'OSM - Rating and Score'!$C$65:$D$70,2,0)*CY$6,2) -> 0.15 | DA8: =ROUND(VLOOKUP(AW8,'OSM - Rating and Score'!$C$8:$D$13,2,0)*DA$6,2) -> 0 | DC8: =ROUND(VLOOKUP(AY8,'OSM - Rating and Score'!$C$75:$D$80,2,0)*DC$6,2) -> 0.15
C10: 2 | E10: Cardiology | G10: Cardiology intervention | I10: High | K10: High | O10: Low Barriers | Q10: Moderate Fit | S10: Partially Ready | U10: Full New Setup | W10: 350 | Y10: 5 | AA10: 0.4 | AC10: =ROUND(Y10*(1+AA10)^5,0) -> 27 | AE10: Medium | AG10: Minimal | AI10: 0 | AK10: High | AM10: Easy | AO10: Easy | AQ10: Moderate | AS10: Moderate | AU10: Moderate | AW10: Medium | AY10: Fast | BA10: =IF(COUNTA(AY10,AW10,AU10,AS10,AQ10,AO10,AM10,AK10,AI10,AG10,AE10,AC10,AA10,Y10,W10,U10,S10,Q10,O10,K10,I10)=21,"✓","✗") -> ✓ | BC10: =IFERROR(SUM(BM10:DC10),"") -> 3.48 | BE10: =IFERROR(LOOKUP(BC10,'OSM - Rating and Score'!$G$103:$I$108,'OSM - Rating and Score'!$C$103:$C$108),"") -> Moderate | BM10: =ROUND(VLOOKUP(I10,'OSM - Rating and Score'!$C$8:$D$13,2,0)*BM$6,2) -> 0 | BO10: =ROUND(VLOOKUP(K10,'OSM - Rating and Score'!$C$8:$D$13,2,0)*BO$6,2) -> 0.2 | BS10: =ROUND(VLOOKUP(O10,'OSM - Rating and Score'!$C$17:$D$22,2,0)*BS$6,2) -> 0.2 | BU10: =ROUND(VLOOKUP(Q10,'OSM - Rating and Score'!$C$56:$D$61,2,0)*BU$6,2) -> 0.21 | BW10: =ROUND(VLOOKUP(S10,'OSM - Rating and Score'!$C$26:$D$31,2,0)*BW$6,2) -> 0.15 | BY10: =ROUND(VLOOKUP(U10,'OSM - Rating and Score'!$C$35:$D$40,2,0)*BY$6,2) -> 0.07 | CC10: =ROUND(LOOKUP(Y10,'OSM - Rating and Score'!$G$85:$I$90,'OSM - Rating and Score'!$D$85:$D$90)*CC$6,2) -> 0.3 | CE10: =ROUND(LOOKUP(AA10,'OSM - Rating and Score'!$G$113:$I$118,'OSM - Rating and Score'!$D$113:$D$118)*CE$6,2) -> 0.32 | CG10: =ROUND(LOOKUP(AC10,'OSM - Rating and Score'!$G$94:$I$99,'OSM - Rating and Score'!$D$85:$D$90)*CG$6,2) -> 0.3 | CI10: =ROUND(VLOOKUP(AE10,'OSM - Rating and Score'!$C$8:$D$13,2,0)*CI$6,2) -> 0.3 | CK10: =ROUND(VLOOKUP(AG10,'OSM - Rating and Score'!$C$8:$D$13,2,0)*CK$6,2) -> 0.04 | CM10: 0 | CO10: =ROUND(VLOOKUP(AK10,'OSM - Rating and Score'!$C$8:$D$13,2,0)*CO$6,2) -> 0.28 | CQ10: =ROUND(VLOOKUP(AM10,'OSM - Rating and Score'!$C$47:$D$52,2,0)*CQ$6,2) -> 0.2 | CS10: =ROUND(VLOOKUP(AO10,'OSM - Rating and Score'!$C$47:$D$52,2,0)*CS$6,2) -> 0.2 | CU10: =ROUND(VLOOKUP(AQ10,'OSM - Rating and Score'!$C$47:$D$52,2,0)*CU$6,2) -> 0.15 | CW10: =ROUND(VLOOKUP(AS10,'OSM - Rating and Score'!$C$47:$D$52,2,0)*CW$6,2) -> 0.21 | CY10: =ROUND(VLOOKUP(AU10,'OSM - Rating and Score'!$C$65:$D$70,2,0)*CY$6,2) -> 0.15 | DA10: =ROUND(VLOOKUP(AW10,'OSM - Rating and Score'!$C$8:$D$13,2,0)*DA$6,2) -> 0 | DC10: =ROUND(VLOOKUP(AY10,'OSM - Rating and Score'!$C$75:$D$80,2,0)*DC$6,2) -> 0.2
C12: 3 | E12: Rehabilitation | G12: Rehabilitation Consumables | I12: Medium | K12: Low | O12: Low Barriers | Q12: Low Fit | S12: Limited Readiness | U12: Major New Team | W12: 60 | Y12: 2 | AA12: 0.15 | AC12: =ROUND(Y12*(1+AA12)^5,0) -> 4 | AE12: High | AG12: Minimal | AI12: 0 | AK12: Medium | AM12: Moderate | AO12: Moderate | AQ12: Easy | AS12: Moderate | AU12: Low Complex | AW12: To Be Assessed | AY12: Fast | BA12: =IF(COUNTA(AY12,AW12,AU12,AS12,AQ12,AO12,AM12,AK12,AI12,AG12,AE12,AC12,AA12,Y12,W12,U12,S12,Q12,O12,K12,I12)=21,"✓","✗") -> ✓ | BC12: =IFERROR(SUM(BM12:DC12),"") -> 2.72 | BE12: =IFERROR(LOOKUP(BC12,'OSM - Rating and Score'!$G$103:$I$108,'OSM - Rating and Score'!$C$103:$C$108),"") -> Moderate | BG12: Market size from Different source | BH12: Number of Patients | BI12: start with the Accoat essentially | BM12: =ROUND(VLOOKUP(I12,'OSM - Rating and Score'!$C$8:$D$13,2,0)*BM$6,2) -> 0 | BO12: =ROUND(VLOOKUP(K12,'OSM - Rating and Score'!$C$8:$D$13,2,0)*BO$6,2) -> 0.1 | BS12: =ROUND(VLOOKUP(O12,'OSM - Rating and Score'!$C$17:$D$22,2,0)*BS$6,2) -> 0.2 | BU12: =ROUND(VLOOKUP(Q12,'OSM - Rating and Score'!$C$56:$D$61,2,0)*BU$6,2) -> 0.14 | BW12: =ROUND(VLOOKUP(S12,'OSM - Rating and Score'!$C$26:$D$31,2,0)*BW$6,2) -> 0.1 | BY12: =ROUND(VLOOKUP(U12,'OSM - Rating and Score'!$C$35:$D$40,2,0)*BY$6,2) -> 0.14 | CC12: =ROUND(LOOKUP(Y12,'OSM - Rating and Score'!$G$85:$I$90,'OSM - Rating and Score'!$D$85:$D$90)*CC$6,2) -> 0.2 | CE12: =ROUND(LOOKUP(AA12,'OSM - Rating and Score'!$G$113:$I$118,'OSM - Rating and Score'!$D$113:$D$118)*CE$6,2) -> 0.08 | CG12: =ROUND(LOOKUP(AC12,'OSM - Rating and Score'!$G$94:$I$99,'OSM - Rating and Score'!$D$85:$D$90)*CG$6,2) -> 0 | CI12: =ROUND(VLOOKUP(AE12,'OSM - Rating and Score'!$C$8:$D$13,2,0)*CI$6,2) -> 0.4 | CK12: =ROUND(VLOOKUP(AG12,'OSM - Rating and Score'!$C$8:$D$13,2,0)*CK$6,2) -> 0.04 | CM12: 0 | CO12: =ROUND(VLOOKUP(AK12,'OSM - Rating and Score'!$C$8:$D$13,2,0)*CO$6,2) -> 0.21 | CQ12: =ROUND(VLOOKUP(AM12,'OSM - Rating and Score'!$C$47:$D$52,2,0)*CQ$6,2) -> 0.15 | CS12: =ROUND(VLOOKUP(AO12,'OSM - Rating and Score'!$C$47:$D$52,2,0)*CS$6,2) -> 0.15 | CU12: =ROUND(VLOOKUP(AQ12,'OSM - Rating and Score'!$C$47:$D$52,2,0)*CU$6,2) -> 0.2 | CW12: =ROUND(VLOOKUP(AS12,'OSM - Rating and Score'!$C$47:$D$52,2,0)*CW$6,2) -> 0.21 | CY12: =ROUND(VLOOKUP(AU12,'OSM - Rating and Score'!$C$65:$D$70,2,0)*CY$6,2) -> 0.2 | DA12: =ROUND(VLOOKUP(AW12,'OSM - Rating and Score'!$C$8:$D$13,2,0)*DA$6,2) -> 0 | DC12: =ROUND(VLOOKUP(AY12,'OSM - Rating and Score'!$C$75:$D$80,2,0)*DC$6,2) -> 0.2
C14: 4 | E14: Rehabiltation | G14: Rehabilitation Device | BA14: =IF(COUNTA(AY14,AW14,AU14,AS14,AQ14,AO14,AM14,AK14,AI14,AG14,AE14,AC14,AA14,Y14,W14,U14,S14,Q14,O14,K14,I14)=21,"✓","✗") -> ✗ | BC14: =IFERROR(SUM(BM14:DC14),"") | BE14: =IFERROR(LOOKUP(BC14,'OSM - Rating and Score'!$G$103:$I$108,'OSM - Rating and Score'!$C$103:$C$108),"") | BM14: =ROUND(VLOOKUP(I14,'OSM - Rating and Score'!$C$8:$D$13,2,0)*BM$6,2) -> #N/A | BO14: =ROUND(VLOOKUP(K14,'OSM - Rating and Score'!$C$8:$D$13,2,0)*BO$6,2) -> #N/A | BS14: =ROUND(VLOOKUP(O14,'OSM - Rating and Score'!$C$17:$D$22,2,0)*BS$6,2) -> #N/A | BU14: =ROUND(VLOOKUP(Q14,'OSM - Rating and Score'!$C$56:$D$61,2,0)*BU$6,2) -> #N/A | BW14: =ROUND(VLOOKUP(S14,'OSM - Rating and Score'!$C$26:$D$31,2,0)*BW$6,2) -> #N/A | BY14: =ROUND(VLOOKUP(U14,'OSM - Rating and Score'!$C$35:$D$40,2,0)*BY$6,2) -> #N/A | CC14: =ROUND(LOOKUP(Y14,'OSM - Rating and Score'!$G$85:$I$90,'OSM - Rating and Score'!$D$85:$D$90)*CC$6,2) -> 0 | CE14: =ROUND(LOOKUP(AA14,'OSM - Rating and Score'!$G$113:$I$118,'OSM - Rating and Score'!$D$113:$D$118)*CE$6,2) -> 0 | CG14: =ROUND(LOOKUP(AC14,'OSM - Rating and Score'!$G$94:$I$99,'OSM - Rating and Score'!$D$85:$D$90)*CG$6,2) -> 0 | CI14: =ROUND(VLOOKUP(AE14,'OSM - Rating and Score'!$C$8:$D$13,2,0)*CI$6,2) -> #N/A | CK14: =ROUND(VLOOKUP(AG14,'OSM - Rating and Score'!$C$8:$D$13,2,0)*CK$6,2) -> #N/A | CM14: 0 | CO14: =ROUND(VLOOKUP(AK14,'OSM - Rating and Score'!$C$8:$D$13,2,0)*CO$6,2) -> #N/A | CQ14: =ROUND(VLOOKUP(AM14,'OSM - Rating and Score'!$C$47:$D$52,2,0)*CQ$6,2) -> #N/A | CS14: =ROUND(VLOOKUP(AO14,'OSM - Rating and Score'!$C$47:$D$52,2,0)*CS$6,2) -> #N/A | CU14: =ROUND(VLOOKUP(AQ14,'OSM - Rating and Score'!$C$47:$D$52,2,0)*CU$6,2) -> #N/A | CW14: =ROUND(VLOOKUP(AS14,'OSM - Rating and Score'!$C$47:$D$52,2,0)*CW$6,2) -> #N/A | CY14: =ROUND(VLOOKUP(AU14,'OSM - Rating and Score'!$C$65:$D$70,2,0)*CY$6,2) -> #N/A | DA14: =ROUND(VLOOKUP(AW14,'OSM - Rating and Score'!$C$8:$D$13,2,0)*DA$6,2) -> #N/A | DC14: =ROUND(VLOOKUP(AY14,'OSM - Rating and Score'!$C$75:$D$80,2,0)*DC$6,2) -> #N/A
C16: 5 | E16: Wound care | G16: negative pressure therapy | I16: High | K16: High | O16: Low Barriers | Q16: Strong Fit | S16: Partially Ready | U16: Some New Staff | W16: 60 | Y16: 4 | AA16: 0.2 | AC16: =ROUND(Y16*(1+AA16)^5,0) -> 10 | AE16: High | AG16: Minimal | AI16: 0 | AK16: Very High | AM16: Very Difficult | AO16: Easy | AQ16: Moderate | AS16: Easy | AU16: Moderate | AW16: Medium | AY16: Very Fast | BA16: =IF(COUNTA(AY16,AW16,AU16,AS16,AQ16,AO16,AM16,AK16,AI16,AG16,AE16,AC16,AA16,Y16,W16,U16,S16,Q16,O16,K16,I16)=21,"✓","✗") -> ✓ | BC16: =IFERROR(SUM(BM16:DC16),"") -> 3.37 | BE16: =IFERROR(LOOKUP(BC16,'OSM - Rating and Score'!$G$103:$I$108,'OSM - Rating and Score'!$C$103:$C$108),"") -> Moderate | BG16: Contarcted with Sunmedic | BH16: we can partcipate in coming tender | BM16: =ROUND(VLOOKUP(I16,'OSM - Rating and Score'!$C$8:$D$13,2,0)*BM$6,2) -> 0 | BO16: =ROUND(VLOOKUP(K16,'OSM - Rating and Score'!$C$8:$D$13,2,0)*BO$6,2) -> 0.2 | BS16: =ROUND(VLOOKUP(O16,'OSM - Rating and Score'!$C$17:$D$22,2,0)*BS$6,2) -> 0.2 | BU16: =ROUND(VLOOKUP(Q16,'OSM - Rating and Score'!$C$56:$D$61,2,0)*BU$6,2) -> 0.28 | BW16: =ROUND(VLOOKUP(S16,'OSM - Rating and Score'!$C$26:$D$31,2,0)*BW$6,2) -> 0.15 | BY16: =ROUND(VLOOKUP(U16,'OSM - Rating and Score'!$C$35:$D$40,2,0)*BY$6,2) -> 0.21 | CC16: =ROUND(LOOKUP(Y16,'OSM - Rating and Score'!$G$85:$I$90,'OSM - Rating and Score'!$D$85:$D$90)*CC$6,2) -> 0.2 | CE16: =ROUND(LOOKUP(AA16,'OSM - Rating and Score'!$G$113:$I$118,'OSM - Rating and Score'!$D$113:$D$118)*CE$6,2) -> 0.16 | CG16: =ROUND(LOOKUP(AC16,'OSM - Rating and Score'!$G$94:$I$99,'OSM - Rating and Score'!$D$85:$D$90)*CG$6,2) -> 0.1 | CI16: =ROUND(VLOOKUP(AE16,'OSM - Rating and Score'!$C$8:$D$13,2,0)*CI$6,2) -> 0.4 | CK16: =ROUND(VLOOKUP(AG16,'OSM - Rating and Score'!$C$8:$D$13,2,0)*CK$6,2) -> 0.04 | CM16: 0 | CO16: =ROUND(VLOOKUP(AK16,'OSM - Rating and Score'!$C$8:$D$13,2,0)*CO$6,2) -> 0.35 | CQ16: =ROUND(VLOOKUP(AM16,'OSM - Rating and Score'!$C$47:$D$52,2,0)*CQ$6,2) -> 0.05 | CS16: =ROUND(VLOOKUP(AO16,'OSM - Rating and Score'!$C$47:$D$52,2,0)*CS$6,2) -> 0.2 | CU16: =ROUND(VLOOKUP(AQ16,'OSM - Rating and Score'!$C$47:$D$52,2,0)*CU$6,2) -> 0.15 | CW16: =ROUND(VLOOKUP(AS16,'OSM - Rating and Score'!$C$47:$D$52,2,0)*CW$6,2) -> 0.28 | CY16: =ROUND(VLOOKUP(AU16,'OSM - Rating and Score'!$C$65:$D$70,2,0)*CY$6,2) -> 0.15 | DA16: =ROUND(VLOOKUP(AW16,'OSM - Rating and Score'!$C$8:$D$13,2,0)*DA$6,2) -> 0 | DC16: =ROUND(VLOOKUP(AY16,'OSM - Rating and Score'!$C$75:$D$80,2,0)*DC$6,2) -> 0.25
C18: 6 | E18: wound care | G18: Regenerative skin | I18: High | K18: High | O18: Low Barriers | Q18: Strong Fit | S18: Partially Ready | U18: Some New Staff | W18: 40 | Y18: 3 | AA18: 0.3 | AC18: =ROUND(Y18*(1+AA18)^5,0) -> 11 | AE18: High | AG18: Medium | AK18: High | AM18: Moderate | AO18: Moderate | AQ18: Easy | AS18: Easy | AU18: Moderate | AW18: To Be Assessed | AY18: Fast | BA18: =IF(COUNTA(AY18,AW18,AU18,AS18,AQ18,AO18,AM18,AK18,AI18,AG18,AE18,AC18,AA18,Y18,W18,U18,S18,Q18,O18,K18,I18)=21,"✓","✗") -> ✗ | BC18: =IFERROR(SUM(BM18:DC18),"") -> 3.51 | BE18: =IFERROR(LOOKUP(BC18,'OSM - Rating and Score'!$G$103:$I$108,'OSM - Rating and Score'!$C$103:$C$108),"") -> Attractive | BG18: under negotation with LifeCell | BH18: if we finaliz the contract in March will catch the tender | BM18: =ROUND(VLOOKUP(I18,'OSM - Rating and Score'!$C$8:$D$13,2,0)*BM$6,2) -> 0 | BO18: =ROUND(VLOOKUP(K18,'OSM - Rating and Score'!$C$8:$D$13,2,0)*BO$6,2) -> 0.2 | BS18: =ROUND(VLOOKUP(O18,'OSM - Rating and Score'!$C$17:$D$22,2,0)*BS$6,2) -> 0.2 | BU18: =ROUND(VLOOKUP(Q18,'OSM - Rating and Score'!$C$56:$D$61,2,0)*BU$6,2) -> 0.28 | BW18: =ROUND(VLOOKUP(S18,'OSM - Rating and Score'!$C$26:$D$31,2,0)*BW$6,2) -> 0.15 | BY18: =ROUND(VLOOKUP(U18,'OSM - Rating and Score'!$C$35:$D$40,2,0)*BY$6,2) -> 0.21 | CC18: =ROUND(LOOKUP(Y18,'OSM - Rating and Score'!$G$85:$I$90,'OSM - Rating and Score'!$D$85:$D$90)*CC$6,2) -> 0.2 | CE18: =ROUND(LOOKUP(AA18,'OSM - Rating and Score'!$G$113:$I$118,'OSM - Rating and Score'!$D$113:$D$118)*CE$6,2) -> 0.24 | CG18: =ROUND(LOOKUP(AC18,'OSM - Rating and Score'!$G$94:$I$99,'OSM - Rating and Score'!$D$85:$D$90)*CG$6,2) -> 0.1 | CI18: =ROUND(VLOOKUP(AE18,'OSM - Rating and Score'!$C$8:$D$13,2,0)*CI$6,2) -> 0.4 | CK18: =ROUND(VLOOKUP(AG18,'OSM - Rating and Score'!$C$8:$D$13,2,0)*CK$6,2) -> 0.12 | CM18: 0 | CO18: =ROUND(VLOOKUP(AK18,'OSM - Rating and Score'!$C$8:$D$13,2,0)*CO$6,2) -> 0.28 | CQ18: =ROUND(VLOOKUP(AM18,'OSM - Rating and Score'!$C$47:$D$52,2,0)*CQ$6,2) -> 0.15 | CS18: =ROUND(VLOOKUP(AO18,'OSM - Rating and Score'!$C$47:$D$52,2,0)*CS$6,2) -> 0.15 | CU18: =ROUND(VLOOKUP(AQ18,'OSM - Rating and Score'!$C$47:$D$52,2,0)*CU$6,2) -> 0.2 | CW18: =ROUND(VLOOKUP(AS18,'OSM - Rating and Score'!$C$47:$D$52,2,0)*CW$6,2) -> 0.28 | CY18: =ROUND(VLOOKUP(AU18,'OSM - Rating and Score'!$C$65:$D$70,2,0)*CY$6,2) -> 0.15 | DA18: =ROUND(VLOOKUP(AW18,'OSM - Rating and Score'!$C$8:$D$13,2,0)*DA$6,2) -> 0 | DC18: =ROUND(VLOOKUP(AY18,'OSM - Rating and Score'!$C$75:$D$80,2,0)*DC$6,2) -> 0.2
C20: 7 | E20: Wound care | G20: Wound Irrigation | I20: Medium | K20: High | O20: Low Barriers | Q20: Strong Fit | S20: Partially Ready | U20: Some New Staff | W20: 30 | Y20: 2 | AA20: 0.3 | AC20: =ROUND(Y20*(1+AA20)^5,0) -> 7 | AE20: High | AG20: Minimal | AI20: 0 | AK20: Medium | AM20: Difficult | AO20: Easy | AQ20: Moderate | AS20: Very Easy | AU20: Moderate | AW20: Minimal | AY20: Medium | BA20: =IF(COUNTA(AY20,AW20,AU20,AS20,AQ20,AO20,AM20,AK20,AI20,AG20,AE20,AC20,AA20,Y20,W20,U20,S20,Q20,O20,K20,I20)=21,"✓","✗") -> ✓ | BC20: =IFERROR(SUM(BM20:DC20),"") -> 3.33 | BE20: =IFERROR(LOOKUP(BC20,'OSM - Rating and Score'!$G$103:$I$108,'OSM - Rating and Score'!$C$103:$C$108),"") -> Moderate | BG20: Pending till June eith Schulke Mayer | BM20: =ROUND(VLOOKUP(I20,'OSM - Rating and Score'!$C$8:$D$13,2,0)*BM$6,2) -> 0 | BO20: =ROUND(VLOOKUP(K20,'OSM - Rating and Score'!$C$8:$D$13,2,0)*BO$6,2) -> 0.2 | BS20: =ROUND(VLOOKUP(O20,'OSM - Rating and Score'!$C$17:$D$22,2,0)*BS$6,2) -> 0.2 | BU20: =ROUND(VLOOKUP(Q20,'OSM - Rating and Score'!$C$56:$D$61,2,0)*BU$6,2) -> 0.28 | BW20: =ROUND(VLOOKUP(S20,'OSM - Rating and Score'!$C$26:$D$31,2,0)*BW$6,2) -> 0.15 | BY20: =ROUND(VLOOKUP(U20,'OSM - Rating and Score'!$C$35:$D$40,2,0)*BY$6,2) -> 0.21 | CC20: =ROUND(LOOKUP(Y20,'OSM - Rating and Score'!$G$85:$I$90,'OSM - Rating and Score'!$D$85:$D$90)*CC$6,2) -> 0.2 | CE20: =ROUND(LOOKUP(AA20,'OSM - Rating and Score'!$G$113:$I$118,'OSM - Rating and Score'!$D$113:$D$118)*CE$6,2) -> 0.24 | CG20: =ROUND(LOOKUP(AC20,'OSM - Rating and Score'!$G$94:$I$99,'OSM - Rating and Score'!$D$85:$D$90)*CG$6,2) -> 0.1 | CI20: =ROUND(VLOOKUP(AE20,'OSM - Rating and Score'!$C$8:$D$13,2,0)*CI$6,2) -> 0.4 | CK20: =ROUND(VLOOKUP(AG20,'OSM - Rating and Score'!$C$8:$D$13,2,0)*CK$6,2) -> 0.04 | CM20: 0 | CO20: =ROUND(VLOOKUP(AK20,'OSM - Rating and Score'!$C$8:$D$13,2,0)*CO$6,2) -> 0.21 | CQ20: =ROUND(VLOOKUP(AM20,'OSM - Rating and Score'!$C$47:$D$52,2,0)*CQ$6,2) -> 0.1 | CS20: =ROUND(VLOOKUP(AO20,'OSM - Rating and Score'!$C$47:$D$52,2,0)*CS$6,2) -> 0.2 | CU20: =ROUND(VLOOKUP(AQ20,'OSM - Rating and Score'!$C$47:$D$52,2,0)*CU$6,2) -> 0.15 | CW20: =ROUND(VLOOKUP(AS20,'OSM - Rating and Score'!$C$47:$D$52,2,0)*CW$6,2) -> 0.35 | CY20: =ROUND(VLOOKUP(AU20,'OSM - Rating and Score'!$C$65:$D$70,2,0)*CY$6,2) -> 0.15 | DA20: =ROUND(VLOOKUP(AW20,'OSM - Rating and Score'!$C$8:$D$13,2,0)*DA$6,2) -> 0 | DC20: =ROUND(VLOOKUP(AY20,'OSM - Rating and Score'!$C$75:$D$80,2,0)*DC$6,2) -> 0.15
C23: 8 | E23: Nebulization | G23: Mesh Nebulizer | I23: Medium | K23: Medium | O23: Medium Barriers | Q23: Strong Fit | S23: Partially Ready | U23: Minor Additions | W23: 80 | Y23: 4 | AA23: 0.2 | AC23: =ROUND(Y23*(1+AA23)^5,0) -> 10 | AE23: High | AG23: Minimal | AK23: High | AM23: Difficult | AO23: Moderate | AQ23: Moderate | AS23: Moderate | AU23: Low Complex | AW23: Minimal | AY23: Medium | BA23: =IF(COUNTA(AY23,AW23,AU23,AS23,AQ23,AO23,AM23,AK23,AI23,AG23,AE23,AC23,AA23,Y23,W23,U23,S23,Q23,O23,K23,I23)=21,"✓","✗") -> ✗ | BC23: =IFERROR(SUM(BM23:DC23),"") -> 3.15 | BE23: =IFERROR(LOOKUP(BC23,'OSM - Rating and Score'!$G$103:$I$108,'OSM - Rating and Score'!$C$103:$C$108),"") -> Moderate | BG23: Abeer consultation | BM23: =ROUND(VLOOKUP(I23,'OSM - Rating and Score'!$C$8:$D$13,2,0)*BM$6,2) -> 0 | BO23: =ROUND(VLOOKUP(K23,'OSM - Rating and Score'!$C$8:$D$13,2,0)*BO$6,2) -> 0.15 | BS23: =ROUND(VLOOKUP(O23,'OSM - Rating and Score'!$C$17:$D$22,2,0)*BS$6,2) -> 0.15 | BU23: =ROUND(VLOOKUP(Q23,'OSM - Rating and Score'!$C$56:$D$61,2,0)*BU$6,2) -> 0.28 | BW23: =ROUND(VLOOKUP(S23,'OSM - Rating and Score'!$C$26:$D$31,2,0)*BW$6,2) -> 0.15 | BY23: =ROUND(VLOOKUP(U23,'OSM - Rating and Score'!$C$35:$D$40,2,0)*BY$6,2) -> 0.28 | CC23: =ROUND(LOOKUP(Y23,'OSM - Rating and Score'!$G$85:$I$90,'OSM - Rating and Score'!$D$85:$D$90)*CC$6,2) -> 0.2 | CE23: =ROUND(LOOKUP(AA23,'OSM - Rating and Score'!$G$113:$I$118,'OSM - Rating and Score'!$D$113:$D$118)*CE$6,2) -> 0.16 | CG23: =ROUND(LOOKUP(AC23,'OSM - Rating and Score'!$G$94:$I$99,'OSM - Rating and Score'!$D$85:$D$90)*CG$6,2) -> 0.1 | CI23: =ROUND(VLOOKUP(AE23,'OSM - Rating and Score'!$C$8:$D$13,2,0)*CI$6,2) -> 0.4 | CK23: =ROUND(VLOOKUP(AG23,'OSM - Rating and Score'!$C$8:$D$13,2,0)*CK$6,2) -> 0.04 | CM23: 0 | CO23: =ROUND(VLOOKUP(AK23,'OSM - Rating and Score'!$C$8:$D$13,2,0)*CO$6,2) -> 0.28 | CQ23: =ROUND(VLOOKUP(AM23,'OSM - Rating and Score'!$C$47:$D$52,2,0)*CQ$6,2) -> 0.1 | CS23: =ROUND(VLOOKUP(AO23,'OSM - Rating and Score'!$C$47:$D$52,2,0)*CS$6,2) -> 0.15 | CU23: =ROUND(VLOOKUP(AQ23,'OSM - Rating and Score'!$C$47:$D$52,2,0)*CU$6,2) -> 0.15 | CW23: =ROUND(VLOOKUP(AS23,'OSM - Rating and Score'!$C$47:$D$52,2,0)*CW$6,2) -> 0.21 | CY23: =ROUND(VLOOKUP(AU23,'OSM - Rating and Score'!$C$65:$D$70,2,0)*CY$6,2) -> 0.2 | DA23: =ROUND(VLOOKUP(AW23,'OSM - Rating and Score'!$C$8:$D$13,2,0)*DA$6,2) -> 0 | DC23: =ROUND(VLOOKUP(AY23,'OSM - Rating and Score'!$C$75:$D$80,2,0)*DC$6,2) -> 0.15
C25: 9 | E25: Drug delivery | G25: Atomizer | M25: need further investigation | AC25: =ROUND(Y25*(1+AA25)^5,0) -> 0 | BA25: =IF(COUNTA(AY25,AW25,AU25,AS25,AQ25,AO25,AM25,AK25,AI25,AG25,AE25,AC25,AA25,Y25,W25,U25,S25,Q25,O25,K25,I25)=21,"✓","✗") -> ✗ | BC25: =IFERROR(SUM(BM25:DC25),"") | BE25: =IFERROR(LOOKUP(BC25,'OSM - Rating and Score'!$G$103:$I$108,'OSM - Rating and Score'!$C$103:$C$108),"") | BG25: Intersurgical | BM25: =ROUND(VLOOKUP(I25,'OSM - Rating and Score'!$C$8:$D$13,2,0)*BM$6,2) -> #N/A | BO25: =ROUND(VLOOKUP(K25,'OSM - Rating and Score'!$C$8:$D$13,2,0)*BO$6,2) -> #N/A | BS25: =ROUND(VLOOKUP(O25,'OSM - Rating and Score'!$C$17:$D$22,2,0)*BS$6,2) -> #N/A | BU25: =ROUND(VLOOKUP(Q25,'OSM - Rating and Score'!$C$56:$D$61,2,0)*BU$6,2) -> #N/A | BW25: =ROUND(VLOOKUP(S25,'OSM - Rating and Score'!$C$26:$D$31,2,0)*BW$6,2) -> #N/A | BY25: =ROUND(VLOOKUP(U25,'OSM - Rating and Score'!$C$35:$D$40,2,0)*BY$6,2) -> #N/A | CC25: =ROUND(LOOKUP(Y25,'OSM - Rating and Score'!$G$85:$I$90,'OSM - Rating and Score'!$D$85:$D$90)*CC$6,2) -> 0 | CE25: =ROUND(LOOKUP(AA25,'OSM - Rating and Score'!$G$113:$I$118,'OSM - Rating and Score'!$D$113:$D$118)*CE$6,2) -> 0 | CG25: =ROUND(LOOKUP(AC25,'OSM - Rating and Score'!$G$94:$I$99,'OSM - Rating and Score'!$D$85:$D$90)*CG$6,2) -> 0 | CI25: =ROUND(VLOOKUP(AE25,'OSM - Rating and Score'!$C$8:$D$13,2,0)*CI$6,2) -> #N/A | CK25: =ROUND(VLOOKUP(AG25,'OSM - Rating and Score'!$C$8:$D$13,2,0)*CK$6,2) -> #N/A | CM25: 0 | CO25: =ROUND(VLOOKUP(AK25,'OSM - Rating and Score'!$C$8:$D$13,2,0)*CO$6,2) -> #N/A | CQ25: =ROUND(VLOOKUP(AM25,'OSM - Rating and Score'!$C$47:$D$52,2,0)*CQ$6,2) -> #N/A | CS25: =ROUND(VLOOKUP(AO25,'OSM - Rating and Score'!$C$47:$D$52,2,0)*CS$6,2) -> #N/A | CU25: =ROUND(VLOOKUP(AQ25,'OSM - Rating and Score'!$C$47:$D$52,2,0)*CU$6,2) -> #N/A | CW25: =ROUND(VLOOKUP(AS25,'OSM - Rating and Score'!$C$47:$D$52,2,0)*CW$6,2) -> #N/A | CY25: =ROUND(VLOOKUP(AU25,'OSM - Rating and Score'!$C$65:$D$70,2,0)*CY$6,2) -> #N/A | DA25: =ROUND(VLOOKUP(AW25,'OSM - Rating and Score'!$C$8:$D$13,2,0)*DA$6,2) -> #N/A | DC25: =ROUND(VLOOKUP(AY25,'OSM - Rating and Score'!$C$75:$D$80,2,0)*DC$6,2) -> #N/A
C27: 10 | E27: Surgical glue | I27: High | K27: Low | O27: High Barriers | Q27: Strong Fit | S27: Limited Readiness | U27: Some New Staff | W27: 35 | Y27: 4 | AA27: 0.1 | AC27: =ROUND(Y27*(1+AA27)^5,0) -> 6 | AE27: High | AG27: Minimal | AI27: 0 | AK27: High | AM27: Moderate | AO27: Moderate | AQ27: Moderate | AS27: Moderate | AU27: Low Complex | AW27: Minimal | AY27: Medium | BA27: =IF(COUNTA(AY27,AW27,AU27,AS27,AQ27,AO27,AM27,AK27,AI27,AG27,AE27,AC27,AA27,Y27,W27,U27,S27,Q27,O27,K27,I27)=21,"✓","✗") -> ✓ | BC27: =IFERROR(SUM(BM27:DC27),"") -> 2.9 | BE27: =IFERROR(LOOKUP(BC27,'OSM - Rating and Score'!$G$103:$I$108,'OSM - Rating and Score'!$C$103:$C$108),"") -> Moderate | BM27: =ROUND(VLOOKUP(I27,'OSM - Rating and Score'!$C$8:$D$13,2,0)*BM$6,2) -> 0 | BO27: =ROUND(VLOOKUP(K27,'OSM - Rating and Score'!$C$8:$D$13,2,0)*BO$6,2) -> 0.1 | BS27: =ROUND(VLOOKUP(O27,'OSM - Rating and Score'!$C$17:$D$22,2,0)*BS$6,2) -> 0.1 | BU27: =ROUND(VLOOKUP(Q27,'OSM - Rating and Score'!$C$56:$D$61,2,0)*BU$6,2) -> 0.28 | BW27: =ROUND(VLOOKUP(S27,'OSM - Rating and Score'!$C$26:$D$31,2,0)*BW$6,2) -> 0.1 | BY27: =ROUND(VLOOKUP(U27,'OSM - Rating and Score'!$C$35:$D$40,2,0)*BY$6,2) -> 0.21 | CC27: =ROUND(LOOKUP(Y27,'OSM - Rating and Score'!$G$85:$I$90,'OSM - Rating and Score'!$D$85:$D$90)*CC$6,2) -> 0.2 | CE27: =ROUND(LOOKUP(AA27,'OSM - Rating and Score'!$G$113:$I$118,'OSM - Rating and Score'!$D$113:$D$118)*CE$6,2) -> 0.08 | CG27: =ROUND(LOOKUP(AC27,'OSM - Rating and Score'!$G$94:$I$99,'OSM - Rating and Score'!$D$85:$D$90)*CG$6,2) -> 0.1 | CI27: =ROUND(VLOOKUP(AE27,'OSM - Rating and Score'!$C$8:$D$13,2,0)*CI$6,2) -> 0.4 | CK27: =ROUND(VLOOKUP(AG27,'OSM - Rating and Score'!$C$8:$D$13,2,0)*CK$6,2) -> 0.04 | CM27: 0 | CO27: =ROUND(VLOOKUP(AK27,'OSM - Rating and Score'!$C$8:$D$13,2,0)*CO$6,2) -> 0.28 | CQ27: =ROUND(VLOOKUP(AM27,'OSM - Rating and Score'!$C$47:$D$52,2,0)*CQ$6,2) -> 0.15 | CS27: =ROUND(VLOOKUP(AO27,'OSM - Rating and Score'!$C$47:$D$52,2,0)*CS$6,2) -> 0.15 | CU27: =ROUND(VLOOKUP(AQ27,'OSM - Rating and Score'!$C$47:$D$52,2,0)*CU$6,2) -> 0.15 | CW27: =ROUND(VLOOKUP(AS27,'OSM - Rating and Score'!$C$47:$D$52,2,0)*CW$6,2) -> 0.21 | CY27: =ROUND(VLOOKUP(AU27,'OSM - Rating and Score'!$C$65:$D$70,2,0)*CY$6,2) -> 0.2 | DA27: =ROUND(VLOOKUP(AW27,'OSM - Rating and Score'!$C$8:$D$13,2,0)*DA$6,2) -> 0 | DC27: =ROUND(VLOOKUP(AY27,'OSM - Rating and Score'!$C$75:$D$80,2,0)*DC$6,2) -> 0.15
C29: 11 | E29: Chyme reinfusion | AC29: =ROUND(Y29*(1+AA29)^5,0) -> 0 | BA29: =IF(COUNTA(AY29,AW29,AU29,AS29,AQ29,AO29,AM29,AK29,AI29,AG29,AE29,AC29,AA29,Y29,W29,U29,S29,Q29,O29,K29,I29)=21,"✓","✗") -> ✗ | BC29: =IFERROR(SUM(BM29:DC29),"") | BE29: =IFERROR(LOOKUP(BC29,'OSM - Rating and Score'!$G$103:$I$108,'OSM - Rating and Score'!$C$103:$C$108),"") | BG29: Communicate with the customer (Nutrient , Colerectal ) | BM29: =ROUND(VLOOKUP(I29,'OSM - Rating and Score'!$C$8:$D$13,2,0)*BM$6,2) -> #N/A | BO29: =ROUND(VLOOKUP(K29,'OSM - Rating and Score'!$C$8:$D$13,2,0)*BO$6,2) -> #N/A | BS29: =ROUND(VLOOKUP(O29,'OSM - Rating and Score'!$C$17:$D$22,2,0)*BS$6,2) -> #N/A | BU29: =ROUND(VLOOKUP(Q29,'OSM - Rating and Score'!$C$56:$D$61,2,0)*BU$6,2) -> #N/A | BW29: =ROUND(VLOOKUP(S29,'OSM - Rating and Score'!$C$26:$D$31,2,0)*BW$6,2) -> #N/A | BY29: =ROUND(VLOOKUP(U29,'OSM - Rating and Score'!$C$35:$D$40,2,0)*BY$6,2) -> #N/A | CC29: =ROUND(LOOKUP(Y29,'OSM - Rating and Score'!$G$85:$I$90,'OSM - Rating and Score'!$D$85:$D$90)*CC$6,2) -> 0 | CE29: =ROUND(LOOKUP(AA29,'OSM - Rating and Score'!$G$113:$I$118,'OSM - Rating and Score'!$D$113:$D$118)*CE$6,2) -> 0 | CG29: =ROUND(LOOKUP(AC29,'OSM - Rating and Score'!$G$94:$I$99,'OSM - Rating and Score'!$D$85:$D$90)*CG$6,2) -> 0 | CI29: =ROUND(VLOOKUP(AE29,'OSM - Rating and Score'!$C$8:$D$13,2,0)*CI$6,2) -> #N/A | CK29: =ROUND(VLOOKUP(AG29,'OSM - Rating and Score'!$C$8:$D$13,2,0)*CK$6,2) -> #N/A | CM29: 0 | CO29: =ROUND(VLOOKUP(AK29,'OSM - Rating and Score'!$C$8:$D$13,2,0)*CO$6,2) -> #N/A | CQ29: =ROUND(VLOOKUP(AM29,'OSM - Rating and Score'!$C$47:$D$52,2,0)*CQ$6,2) -> #N/A | CS29: =ROUND(VLOOKUP(AO29,'OSM - Rating and Score'!$C$47:$D$52,2,0)*CS$6,2) -> #N/A | CU29: =ROUND(VLOOKUP(AQ29,'OSM - Rating and Score'!$C$47:$D$52,2,0)*CU$6,2) -> #N/A | CW29: =ROUND(VLOOKUP(AS29,'OSM - Rating and Score'!$C$47:$D$52,2,0)*CW$6,2) -> #N/A | CY29: =ROUND(VLOOKUP(AU29,'OSM - Rating and Score'!$C$65:$D$70,2,0)*CY$6,2) -> #N/A | DA29: =ROUND(VLOOKUP(AW29,'OSM - Rating and Score'!$C$8:$D$13,2,0)*DA$6,2) -> #N/A | DC29: =ROUND(VLOOKUP(AY29,'OSM - Rating and Score'!$C$75:$D$80,2,0)*DC$6,2) -> #N/A
C31: 12 | E31: Peripeheral intervention intervention | I31: High | K31: Medium | O31: Medium Barriers | Q31: Low Fit | S31: Partially Ready | U31: Some New Staff | W31: 250 | Y31: 2 | AA31: 0.5 | AC31: =ROUND(Y31*(1+AA31)^5,0) -> 15 | AE31: Medium | AG31: Minimal | AK31: High | AM31: Easy | AO31: Moderate | AQ31: Moderate | AS31: Moderate | AU31: Complex | AW31: Medium | AY31: Fast | BA31: =IF(COUNTA(AY31,AW31,AU31,AS31,AQ31,AO31,AM31,AK31,AI31,AG31,AE31,AC31,AA31,Y31,W31,U31,S31,Q31,O31,K31,I31)=21,"✓","✗") -> ✗ | BC31: =IFERROR(SUM(BM31:DC31),"") -> 3.23 | BE31: =IFERROR(LOOKUP(BC31,'OSM - Rating and Score'!$G$103:$I$108,'OSM - Rating and Score'!$C$103:$C$108),"") -> Moderate | BM31: =ROUND(VLOOKUP(I31,'OSM - Rating and Score'!$C$8:$D$13,2,0)*BM$6,2) -> 0 | BO31: =ROUND(VLOOKUP(K31,'OSM - Rating and Score'!$C$8:$D$13,2,0)*BO$6,2) -> 0.15 | BS31: =ROUND(VLOOKUP(O31,'OSM - Rating and Score'!$C$17:$D$22,2,0)*BS$6,2) -> 0.15 | BU31: =ROUND(VLOOKUP(Q31,'OSM - Rating and Score'!$C$56:$D$61,2,0)*BU$6,2) -> 0.14 | BW31: =ROUND(VLOOKUP(S31,'OSM - Rating and Score'!$C$26:$D$31,2,0)*BW$6,2) -> 0.15 | BY31: =ROUND(VLOOKUP(U31,'OSM - Rating and Score'!$C$35:$D$40,2,0)*BY$6,2) -> 0.21 | CC31: =ROUND(LOOKUP(Y31,'OSM - Rating and Score'!$G$85:$I$90,'OSM - Rating and Score'!$D$85:$D$90)*CC$6,2) -> 0.2 | CE31: =ROUND(LOOKUP(AA31,'OSM - Rating and Score'!$G$113:$I$118,'OSM - Rating and Score'!$D$113:$D$118)*CE$6,2) -> 0.4 | CG31: =ROUND(LOOKUP(AC31,'OSM - Rating and Score'!$G$94:$I$99,'OSM - Rating and Score'!$D$85:$D$90)*CG$6,2) -> 0.2 | CI31: =ROUND(VLOOKUP(AE31,'OSM - Rating and Score'!$C$8:$D$13,2,0)*CI$6,2) -> 0.3 | CK31: =ROUND(VLOOKUP(AG31,'OSM - Rating and Score'!$C$8:$D$13,2,0)*CK$6,2) -> 0.04 | CM31: 0 | CO31: =ROUND(VLOOKUP(AK31,'OSM - Rating and Score'!$C$8:$D$13,2,0)*CO$6,2) -> 0.28 | CQ31: =ROUND(VLOOKUP(AM31,'OSM - Rating and Score'!$C$47:$D$52,2,0)*CQ$6,2) -> 0.2 | CS31: =ROUND(VLOOKUP(AO31,'OSM - Rating and Score'!$C$47:$D$52,2,0)*CS$6,2) -> 0.15 | CU31: =ROUND(VLOOKUP(AQ31,'OSM - Rating and Score'!$C$47:$D$52,2,0)*CU$6,2) -> 0.15 | CW31: =ROUND(VLOOKUP(AS31,'OSM - Rating and Score'!$C$47:$D$52,2,0)*CW$6,2) -> 0.21 | CY31: =ROUND(VLOOKUP(AU31,'OSM - Rating and Score'!$C$65:$D$70,2,0)*CY$6,2) -> 0.1 | DA31: =ROUND(VLOOKUP(AW31,'OSM - Rating and Score'!$C$8:$D$13,2,0)*DA$6,2) -> 0 | DC31: =ROUND(VLOOKUP(AY31,'OSM - Rating and Score'!$C$75:$D$80,2,0)*DC$6,2) -> 0.2
C33: 14 | E33: Neurovascular | I33: High | K33: Medium | O33: High Barriers | Q33: Low Fit | S33: Limited Readiness | U33: Minor Additions | W33: 150 | Y33: 2 | AA33: 0.4 | AC33: =ROUND(Y33*(1+AA33)^5,0) -> 11 | AE33: High | AG33: Minimal | AK33: Low | AM33: Moderate | AO33: Moderate | AQ33: Moderate | AS33: Moderate | AU33: Complex | AW33: Minimal | AY33: Medium | BA33: =IF(COUNTA(AY33,AW33,AU33,AS33,AQ33,AO33,AM33,AK33,AI33,AG33,AE33,AC33,AA33,Y33,W33,U33,S33,Q33,O33,K33,I33)=21,"✓","✗") -> ✗ | BC33: =IFERROR(SUM(BM33:DC33),"") -> 2.88 | BE33: =IFERROR(LOOKUP(BC33,'OSM - Rating and Score'!$G$103:$I$108,'OSM - Rating and Score'!$C$103:$C$108),"") -> Moderate | BG33: Exploring COOK medical | BM33: =ROUND(VLOOKUP(I33,'OSM - Rating and Score'!$C$8:$D$13,2,0)*BM$6,2) -> 0 | BO33: =ROUND(VLOOKUP(K33,'OSM - Rating and Score'!$C$8:$D$13,2,0)*BO$6,2) -> 0.15 | BS33: =ROUND(VLOOKUP(O33,'OSM - Rating and Score'!$C$17:$D$22,2,0)*BS$6,2) -> 0.1 | BU33: =ROUND(VLOOKUP(Q33,'OSM - Rating and Score'!$C$56:$D$61,2,0)*BU$6,2) -> 0.14 | BW33: =ROUND(VLOOKUP(S33,'OSM - Rating and Score'!$C$26:$D$31,2,0)*BW$6,2) -> 0.1 | BY33: =ROUND(VLOOKUP(U33,'OSM - Rating and Score'!$C$35:$D$40,2,0)*BY$6,2) -> 0.28 | CC33: =ROUND(LOOKUP(Y33,'OSM - Rating and Score'!$G$85:$I$90,'OSM - Rating and Score'!$D$85:$D$90)*CC$6,2) -> 0.2 | CE33: =ROUND(LOOKUP(AA33,'OSM - Rating and Score'!$G$113:$I$118,'OSM - Rating and Score'!$D$113:$D$118)*CE$6,2) -> 0.32 | CG33: =ROUND(LOOKUP(AC33,'OSM - Rating and Score'!$G$94:$I$99,'OSM - Rating and Score'!$D$85:$D$90)*CG$6,2) -> 0.1 | CI33: =ROUND(VLOOKUP(AE33,'OSM - Rating and Score'!$C$8:$D$13,2,0)*CI$6,2) -> 0.4 | CK33: =ROUND(VLOOKUP(AG33,'OSM - Rating and Score'!$C$8:$D$13,2,0)*CK$6,2) -> 0.04 | CM33: 0 | CO33: =ROUND(VLOOKUP(AK33,'OSM - Rating and Score'!$C$8:$D$13,2,0)*CO$6,2) -> 0.14 | CQ33: =ROUND(VLOOKUP(AM33,'OSM - Rating and Score'!$C$47:$D$52,2,0)*CQ$6,2) -> 0.15 | CS33: =ROUND(VLOOKUP(AO33,'OSM - Rating and Score'!$C$47:$D$52,2,0)*CS$6,2) -> 0.15 | CU33: =ROUND(VLOOKUP(AQ33,'OSM - Rating and Score'!$C$47:$D$52,2,0)*CU$6,2) -> 0.15 | CW33: =ROUND(VLOOKUP(AS33,'OSM - Rating and Score'!$C$47:$D$52,2,0)*CW$6,2) -> 0.21 | CY33: =ROUND(VLOOKUP(AU33,'OSM - Rating and Score'!$C$65:$D$70,2,0)*CY$6,2) -> 0.1 | DA33: =ROUND(VLOOKUP(AW33,'OSM - Rating and Score'!$C$8:$D$13,2,0)*DA$6,2) -> 0 | DC33: =ROUND(VLOOKUP(AY33,'OSM - Rating and Score'!$C$75:$D$80,2,0)*DC$6,2) -> 0.15
C35: 15 | E35: Strcture haert disease | I35: High | K35: Medium | O35: Medium Barriers | Q35: Low Fit | S35: Limited Readiness | U35: Some New Staff | W35: 160 | Y35: 2 | AA35: 0.5 | AC35: =ROUND(Y35*(1+AA35)^5,0) -> 15 | AE35: High | AG35: Minimal | AK35: Medium | AM35: Difficult | AO35: Moderate | AQ35: Moderate | AS35: Difficult | AU35: Moderate | AW35: Minimal | AY35: Medium | BA35: =IF(COUNTA(AY35,AW35,AU35,AS35,AQ35,AO35,AM35,AK35,AI35,AG35,AE35,AC35,AA35,Y35,W35,U35,S35,Q35,O35,K35,I35)=21,"✓","✗") -> ✗ | BC35: =IFERROR(SUM(BM35:DC35),"") -> 3.04 | BE35: =IFERROR(LOOKUP(BC35,'OSM - Rating and Score'!$G$103:$I$108,'OSM - Rating and Score'!$C$103:$C$108),"") -> Moderate | BG35: Connect with BALT | BM35: =ROUND(VLOOKUP(I35,'OSM - Rating and Score'!$C$8:$D$13,2,0)*BM$6,2) -> 0 | BO35: =ROUND(VLOOKUP(K35,'OSM - Rating and Score'!$C$8:$D$13,2,0)*BO$6,2) -> 0.15 | BS35: =ROUND(VLOOKUP(O35,'OSM - Rating and Score'!$C$17:$D$22,2,0)*BS$6,2) -> 0.15 | BU35: =ROUND(VLOOKUP(Q35,'OSM - Rating and Score'!$C$56:$D$61,2,0)*BU$6,2) -> 0.14 | BW35: =ROUND(VLOOKUP(S35,'OSM - Rating and Score'!$C$26:$D$31,2,0)*BW$6,2) -> 0.1 | BY35: =ROUND(VLOOKUP(U35,'OSM - Rating and Score'!$C$35:$D$40,2,0)*BY$6,2) -> 0.21 | CC35: =ROUND(LOOKUP(Y35,'OSM - Rating and Score'!$G$85:$I$90,'OSM - Rating and Score'!$D$85:$D$90)*CC$6,2) -> 0.2 | CE35: =ROUND(LOOKUP(AA35,'OSM - Rating and Score'!$G$113:$I$118,'OSM - Rating and Score'!$D$113:$D$118)*CE$6,2) -> 0.4 | CG35: =ROUND(LOOKUP(AC35,'OSM - Rating and Score'!$G$94:$I$99,'OSM - Rating and Score'!$D$85:$D$90)*CG$6,2) -> 0.2 | CI35: =ROUND(VLOOKUP(AE35,'OSM - Rating and Score'!$C$8:$D$13,2,0)*CI$6,2) -> 0.4 | CK35: =ROUND(VLOOKUP(AG35,'OSM - Rating and Score'!$C$8:$D$13,2,0)*CK$6,2) -> 0.04 | CM35: 0 | CO35: =ROUND(VLOOKUP(AK35,'OSM - Rating and Score'!$C$8:$D$13,2,0)*CO$6,2) -> 0.21 | CQ35: =ROUND(VLOOKUP(AM35,'OSM - Rating and Score'!$C$47:$D$52,2,0)*CQ$6,2) -> 0.1 | CS35: =ROUND(VLOOKUP(AO35,'OSM - Rating and Score'!$C$47:$D$52,2,0)*CS$6,2) -> 0.15 | CU35: =ROUND(VLOOKUP(AQ35,'OSM - Rating and Score'!$C$47:$D$52,2,0)*CU$6,2) -> 0.15 | CW35: =ROUND(VLOOKUP(AS35,'OSM - Rating and Score'!$C$47:$D$52,2,0)*CW$6,2) -> 0.14 | CY35: =ROUND(VLOOKUP(AU35,'OSM - Rating and Score'!$C$65:$D$70,2,0)*CY$6,2) -> 0.15 | DA35: =ROUND(VLOOKUP(AW35,'OSM - Rating and Score'!$C$8:$D$13,2,0)*DA$6,2) -> 0 | DC35: =ROUND(VLOOKUP(AY35,'OSM - Rating and Score'!$C$75:$D$80,2,0)*DC$6,2) -> 0.15
C37: 16 | E37: Vascular Surgery | I37: Medium | K37: Medium | O37: Medium Barriers | Q37: Low Fit | S37: Limited Readiness | U37: Some New Staff | W37: 100 | Y37: 1 | AA37: 0.2 | AC37: =ROUND(Y37*(1+AA37)^5,0) -> 2 | AE37: Medium | AG37: Minimal | AK37: Medium | AM37: Moderate | AO37: Moderate | AQ37: Easy | AS37: Easy | AU37: Moderate | AW37: Minimal | AY37: Fast | BA37: =IF(COUNTA(AY37,AW37,AU37,AS37,AQ37,AO37,AM37,AK37,AI37,AG37,AE37,AC37,AA37,Y37,W37,U37,S37,Q37,O37,K37,I37)=21,"✓","✗") -> ✗ | BC37: =IFERROR(SUM(BM37:DC37),"") -> 2.79 | BE37: =IFERROR(LOOKUP(BC37,'OSM - Rating and Score'!$G$103:$I$108,'OSM - Rating and Score'!$C$103:$C$108),"") -> Moderate | BG37: Explore the Dialysis | BM37: =ROUND(VLOOKUP(I37,'OSM - Rating and Score'!$C$8:$D$13,2,0)*BM$6,2) -> 0 | BO37: =ROUND(VLOOKUP(K37,'OSM - Rating and Score'!$C$8:$D$13,2,0)*BO$6,2) -> 0.15 | BS37: =ROUND(VLOOKUP(O37,'OSM - Rating and Score'!$C$17:$D$22,2,0)*BS$6,2) -> 0.15 | BU37: =ROUND(VLOOKUP(Q37,'OSM - Rating and Score'!$C$56:$D$61,2,0)*BU$6,2) -> 0.14 | BW37: =ROUND(VLOOKUP(S37,'OSM - Rating and Score'!$C$26:$D$31,2,0)*BW$6,2) -> 0.1 | BY37: =ROUND(VLOOKUP(U37,'OSM - Rating and Score'!$C$35:$D$40,2,0)*BY$6,2) -> 0.21 | CC37: =ROUND(LOOKUP(Y37,'OSM - Rating and Score'!$G$85:$I$90,'OSM - Rating and Score'!$D$85:$D$90)*CC$6,2) -> 0.2 | CE37: =ROUND(LOOKUP(AA37,'OSM - Rating and Score'!$G$113:$I$118,'OSM - Rating and Score'!$D$113:$D$118)*CE$6,2) -> 0.16 | CG37: =ROUND(LOOKUP(AC37,'OSM - Rating and Score'!$G$94:$I$99,'OSM - Rating and Score'!$D$85:$D$90)*CG$6,2) -> 0 | CI37: =ROUND(VLOOKUP(AE37,'OSM - Rating and Score'!$C$8:$D$13,2,0)*CI$6,2) -> 0.3 | CK37: =ROUND(VLOOKUP(AG37,'OSM - Rating and Score'!$C$8:$D$13,2,0)*CK$6,2) -> 0.04 | CM37: 0 | CO37: =ROUND(VLOOKUP(AK37,'OSM - Rating and Score'!$C$8:$D$13,2,0)*CO$6,2) -> 0.21 | CQ37: =ROUND(VLOOKUP(AM37,'OSM - Rating and Score'!$C$47:$D$52,2,0)*CQ$6,2) -> 0.15 | CS37: =ROUND(VLOOKUP(AO37,'OSM - Rating and Score'!$C$47:$D$52,2,0)*CS$6,2) -> 0.15 | CU37: =ROUND(VLOOKUP(AQ37,'OSM - Rating and Score'!$C$47:$D$52,2,0)*CU$6,2) -> 0.2 | CW37: =ROUND(VLOOKUP(AS37,'OSM - Rating and Score'!$C$47:$D$52,2,0)*CW$6,2) -> 0.28 | CY37: =ROUND(VLOOKUP(AU37,'OSM - Rating and Score'!$C$65:$D$70,2,0)*CY$6,2) -> 0.15 | DA37: =ROUND(VLOOKUP(AW37,'OSM - Rating and Score'!$C$8:$D$13,2,0)*DA$6,2) -> 0 | DC37: =ROUND(VLOOKUP(AY37,'OSM - Rating and Score'!$C$75:$D$80,2,0)*DC$6,2) -> 0.2
C39: 17 | E39: Cardiothoracic Surgery | I39: High | K39: Medium | O39: Medium Barriers | Q39: Low Fit | S39: Limited Readiness | U39: Some New Staff | W39: 300 | Y39: 3 | AA39: 0.4 | AC39: =ROUND(Y39*(1+AA39)^5,0) -> 16 | AE39: High | AG39: Minimal | AK39: Medium | AM39: Moderate | AO39: Moderate | AQ39: Easy | AS39: Moderate | AU39: Low Complex | AW39: Low | AY39: Medium | BA39: =IF(COUNTA(AY39,AW39,AU39,AS39,AQ39,AO39,AM39,AK39,AI39,AG39,AE39,AC39,AA39,Y39,W39,U39,S39,Q39,O39,K39,I39)=21,"✓","✗") -> ✗ | BC39: =IFERROR(SUM(BM39:DC39),"") -> 3.18 | BE39: =IFERROR(LOOKUP(BC39,'OSM - Rating and Score'!$G$103:$I$108,'OSM - Rating and Score'!$C$103:$C$108),"") -> Moderate | BM39: =ROUND(VLOOKUP(I39,'OSM - Rating and Score'!$C$8:$D$13,2,0)*BM$6,2) -> 0 | BO39: =ROUND(VLOOKUP(K39,'OSM - Rating and Score'!$C$8:$D$13,2,0)*BO$6,2) -> 0.15 | BS39: =ROUND(VLOOKUP(O39,'OSM - Rating and Score'!$C$17:$D$22,2,0)*BS$6,2) -> 0.15 | BU39: =ROUND(VLOOKUP(Q39,'OSM - Rating and Score'!$C$56:$D$61,2,0)*BU$6,2) -> 0.14 | BW39: =ROUND(VLOOKUP(S39,'OSM - Rating and Score'!$C$26:$D$31,2,0)*BW$6,2) -> 0.1 | BY39: =ROUND(VLOOKUP(U39,'OSM - Rating and Score'!$C$35:$D$40,2,0)*BY$6,2) -> 0.21 | CC39: =ROUND(LOOKUP(Y39,'OSM - Rating and Score'!$G$85:$I$90,'OSM - Rating and Score'!$D$85:$D$90)*CC$6,2) -> 0.2 | CE39: =ROUND(LOOKUP(AA39,'OSM - Rating and Score'!$G$113:$I$118,'OSM - Rating and Score'!$D$113:$D$118)*CE$6,2) -> 0.32 | CG39: =ROUND(LOOKUP(AC39,'OSM - Rating and Score'!$G$94:$I$99,'OSM - Rating and Score'!$D$85:$D$90)*CG$6,2) -> 0.2 | CI39: =ROUND(VLOOKUP(AE39,'OSM - Rating and Score'!$C$8:$D$13,2,0)*CI$6,2) -> 0.4 | CK39: =ROUND(VLOOKUP(AG39,'OSM - Rating and Score'!$C$8:$D$13,2,0)*CK$6,2) -> 0.04 | CM39: 0 | CO39: =ROUND(VLOOKUP(AK39,'OSM - Rating and Score'!$C$8:$D$13,2,0)*CO$6,2) -> 0.21 | CQ39: =ROUND(VLOOKUP(AM39,'OSM - Rating and Score'!$C$47:$D$52,2,0)*CQ$6,2) -> 0.15 | CS39: =ROUND(VLOOKUP(AO39,'OSM - Rating and Score'!$C$47:$D$52,2,0)*CS$6,2) -> 0.15 | CU39: =ROUND(VLOOKUP(AQ39,'OSM - Rating and Score'!$C$47:$D$52,2,0)*CU$6,2) -> 0.2 | CW39: =ROUND(VLOOKUP(AS39,'OSM - Rating and Score'!$C$47:$D$52,2,0)*CW$6,2) -> 0.21 | CY39: =ROUND(VLOOKUP(AU39,'OSM - Rating and Score'!$C$65:$D$70,2,0)*CY$6,2) -> 0.2 | DA39: =ROUND(VLOOKUP(AW39,'OSM - Rating and Score'!$C$8:$D$13,2,0)*DA$6,2) -> 0 | DC39: =ROUND(VLOOKUP(AY39,'OSM - Rating and Score'!$C$75:$D$80,2,0)*DC$6,2) -> 0.15
AA40: 20
C41: 18 | E41: Vascular access | I41: High | K41: High | O41: Low Barriers | Q41: Strong Fit | S41: Ready | U41: No New Team | W41: 80 | Y41: 5 | AA41: 0.2 | AC41: =ROUND(Y41*(1+AA41)^5,0) -> 12 | AE41: Medium | AG41: Minimal | AK41: High | AM41: Easy | AO41: Moderate | AQ41: Moderate | AS41: Easy | AU41: Low Complex | AW41: Medium | AY41: Fast | BA41: =IF(COUNTA(AY41,AW41,AU41,AS41,AQ41,AO41,AM41,AK41,AI41,AG41,AE41,AC41,AA41,Y41,W41,U41,S41,Q41,O41,K41,I41)=21,"✓","✗") -> ✗ | BC41: =IFERROR(SUM(BM41:DC41),"") -> 3.59 | BE41: =IFERROR(LOOKUP(BC41,'OSM - Rating and Score'!$G$103:$I$108,'OSM - Rating and Score'!$C$103:$C$108),"") -> Attractive | BG41: CVS in the tender communication | BM41: =ROUND(VLOOKUP(I41,'OSM - Rating and Score'!$C$8:$D$13,2,0)*BM$6,2) -> 0 | BO41: =ROUND(VLOOKUP(K41,'OSM - Rating and Score'!$C$8:$D$13,2,0)*BO$6,2) -> 0.2 | BS41: =ROUND(VLOOKUP(O41,'OSM - Rating and Score'!$C$17:$D$22,2,0)*BS$6,2) -> 0.2 | BU41: =ROUND(VLOOKUP(Q41,'OSM - Rating and Score'!$C$56:$D$61,2,0)*BU$6,2) -> 0.28 | BW41: =ROUND(VLOOKUP(S41,'OSM - Rating and Score'!$C$26:$D$31,2,0)*BW$6,2) -> 0.2 | BY41: =ROUND(VLOOKUP(U41,'OSM - Rating and Score'!$C$35:$D$40,2,0)*BY$6,2) -> 0.35 | CC41: =ROUND(LOOKUP(Y41,'OSM - Rating and Score'!$G$85:$I$90,'OSM - Rating and Score'!$D$85:$D$90)*CC$6,2) -> 0.3 | CE41: =ROUND(LOOKUP(AA41,'OSM - Rating and Score'!$G$113:$I$118,'OSM - Rating and Score'!$D$113:$D$118)*CE$6,2) -> 0.16 | CG41: =ROUND(LOOKUP(AC41,'OSM - Rating and Score'!$G$94:$I$99,'OSM - Rating and Score'!$D$85:$D$90)*CG$6,2) -> 0.1 | CI41: =ROUND(VLOOKUP(AE41,'OSM - Rating and Score'!$C$8:$D$13,2,0)*CI$6,2) -> 0.3 | CK41: =ROUND(VLOOKUP(AG41,'OSM - Rating and Score'!$C$8:$D$13,2,0)*CK$6,2) -> 0.04 | CM41: 0 | CO41: =ROUND(VLOOKUP(AK41,'OSM - Rating and Score'!$C$8:$D$13,2,0)*CO$6,2) -> 0.28 | CQ41: =ROUND(VLOOKUP(AM41,'OSM - Rating and Score'!$C$47:$D$52,2,0)*CQ$6,2) -> 0.2 | CS41: =ROUND(VLOOKUP(AO41,'OSM - Rating and Score'!$C$47:$D$52,2,0)*CS$6,2) -> 0.15 | CU41: =ROUND(VLOOKUP(AQ41,'OSM - Rating and Score'!$C$47:$D$52,2,0)*CU$6,2) -> 0.15 | CW41: =ROUND(VLOOKUP(AS41,'OSM - Rating and Score'!$C$47:$D$52,2,0)*CW$6,2) -> 0.28 | CY41: =ROUND(VLOOKUP(AU41,'OSM - Rating and Score'!$C$65:$D$70,2,0)*CY$6,2) -> 0.2 | DA41: =ROUND(VLOOKUP(AW41,'OSM - Rating and Score'!$C$8:$D$13,2,0)*DA$6,2) -> 0 | DC41: =ROUND(VLOOKUP(AY41,'OSM - Rating and Score'!$C$75:$D$80,2,0)*DC$6,2) -> 0.2
C43: 19 | E43: Cath Lock Solution | G43: Theradial | I43: High | K43: High | O43: Medium Barriers | Q43: Moderate Fit | S43: Partially Ready | U43: Major New Team | W43: 100 | Y43: 5 | AA43: 0.4 | AC43: =ROUND(Y43*(1+AA43)^5,0) -> 27 | AE43: High | AG43: To Be Assessed | AK43: High | AM43: Moderate | AO43: Moderate | AQ43: Difficult | AS43: Moderate | AU43: Low Complex | AW43: High | AY43: Fast | BA43: =IF(COUNTA(AY43,AW43,AU43,AS43,AQ43,AO43,AM43,AK43,AI43,AG43,AE43,AC43,AA43,Y43,W43,U43,S43,Q43,O43,K43,I43)=21,"✓","✗") -> ✗ | BC43: =IFERROR(SUM(BM43:DC43),"") -> 3.46 | BE43: =IFERROR(LOOKUP(BC43,'OSM - Rating and Score'!$G$103:$I$108,'OSM - Rating and Score'!$C$103:$C$108),"") -> Moderate | BG43: Contarcting with Thredial / Starting Regsiteration with RA | BM43: =ROUND(VLOOKUP(I43,'OSM - Rating and Score'!$C$8:$D$13,2,0)*BM$6,2) -> 0 | BO43: =ROUND(VLOOKUP(K43,'OSM - Rating and Score'!$C$8:$D$13,2,0)*BO$6,2) -> 0.2 | BS43: =ROUND(VLOOKUP(O43,'OSM - Rating and Score'!$C$17:$D$22,2,0)*BS$6,2) -> 0.15 | BU43: =ROUND(VLOOKUP(Q43,'OSM - Rating and Score'!$C$56:$D$61,2,0)*BU$6,2) -> 0.21 | BW43: =ROUND(VLOOKUP(S43,'OSM - Rating and Score'!$C$26:$D$31,2,0)*BW$6,2) -> 0.15 | BY43: =ROUND(VLOOKUP(U43,'OSM - Rating and Score'!$C$35:$D$40,2,0)*BY$6,2) -> 0.14 | CC43: =ROUND(LOOKUP(Y43,'OSM - Rating and Score'!$G$85:$I$90,'OSM - Rating and Score'!$D$85:$D$90)*CC$6,2) -> 0.3 | CE43: =ROUND(LOOKUP(AA43,'OSM - Rating and Score'!$G$113:$I$118,'OSM - Rating and Score'!$D$113:$D$118)*CE$6,2) -> 0.32 | CG43: =ROUND(LOOKUP(AC43,'OSM - Rating and Score'!$G$94:$I$99,'OSM - Rating and Score'!$D$85:$D$90)*CG$6,2) -> 0.3 | CI43: =ROUND(VLOOKUP(AE43,'OSM - Rating and Score'!$C$8:$D$13,2,0)*CI$6,2) -> 0.4 | CK43: =ROUND(VLOOKUP(AG43,'OSM - Rating and Score'!$C$8:$D$13,2,0)*CK$6,2) -> 0 | CM43: 0 | CO43: =ROUND(VLOOKUP(AK43,'OSM - Rating and Score'!$C$8:$D$13,2,0)*CO$6,2) -> 0.28 | CQ43: =ROUND(VLOOKUP(AM43,'OSM - Rating and Score'!$C$47:$D$52,2,0)*CQ$6,2) -> 0.15 | CS43: =ROUND(VLOOKUP(AO43,'OSM - Rating and Score'!$C$47:$D$52,2,0)*CS$6,2) -> 0.15 | CU43: =ROUND(VLOOKUP(AQ43,'OSM - Rating and Score'!$C$47:$D$52,2,0)*CU$6,2) -> 0.1 | CW43: =ROUND(VLOOKUP(AS43,'OSM - Rating and Score'!$C$47:$D$52,2,0)*CW$6,2) -> 0.21 | CY43: =ROUND(VLOOKUP(AU43,'OSM - Rating and Score'!$C$65:$D$70,2,0)*CY$6,2) -> 0.2 | DA43: =ROUND(VLOOKUP(AW43,'OSM - Rating and Score'!$C$8:$D$13,2,0)*DA$6,2) -> 0 | DC43: =ROUND(VLOOKUP(AY43,'OSM - Rating and Score'!$C$75:$D$80,2,0)*DC$6,2) -> 0.2
C45: 20 | E45: POC -Blood gas | G45: Medcaptain/ Fortress Diagnostic IVD | I45: High | K45: Low | O45: High Barriers | Q45: Low Fit | S45: Limited Readiness | U45: Major New Team | W45: 200 | Y45: 5 | AA45: 0.2 | AC45: =ROUND(Y45*(1+AA45)^5,0) -> 12 | AE45: High | AG45: Minimal | AI45: 0.5 | AK45: High | AM45: Easy | AO45: Moderate | AQ45: Moderate | AS45: Moderate | AU45: Moderate | AW45: Minimal | AY45: Fast | BA45: =IF(COUNTA(AY45,AW45,AU45,AS45,AQ45,AO45,AM45,AK45,AI45,AG45,AE45,AC45,AA45,Y45,W45,U45,S45,Q45,O45,K45,I45)=21,"✓","✗") -> ✓ | BC45: =IFERROR(SUM(BM45:DC45),"") -> 2.92 | BE45: =IFERROR(LOOKUP(BC45,'OSM - Rating and Score'!$G$103:$I$108,'OSM - Rating and Score'!$C$103:$C$108),"") -> Moderate | BG45: Poland company | BM45: =ROUND(VLOOKUP(I45,'OSM - Rating and Score'!$C$8:$D$13,2,0)*BM$6,2) -> 0 | BO45: =ROUND(VLOOKUP(K45,'OSM - Rating and Score'!$C$8:$D$13,2,0)*BO$6,2) -> 0.1 | BS45: =ROUND(VLOOKUP(O45,'OSM - Rating and Score'!$C$17:$D$22,2,0)*BS$6,2) -> 0.1 | BU45: =ROUND(VLOOKUP(Q45,'OSM - Rating and Score'!$C$56:$D$61,2,0)*BU$6,2) -> 0.14 | BW45: =ROUND(VLOOKUP(S45,'OSM - Rating and Score'!$C$26:$D$31,2,0)*BW$6,2) -> 0.1 | BY45: =ROUND(VLOOKUP(U45,'OSM - Rating and Score'!$C$35:$D$40,2,0)*BY$6,2) -> 0.14 | CC45: =ROUND(LOOKUP(Y45,'OSM - Rating and Score'!$G$85:$I$90,'OSM - Rating and Score'!$D$85:$D$90)*CC$6,2) -> 0.3 | CE45: =ROUND(LOOKUP(AA45,'OSM - Rating and Score'!$G$113:$I$118,'OSM - Rating and Score'!$D$113:$D$118)*CE$6,2) -> 0.16 | CG45: =ROUND(LOOKUP(AC45,'OSM - Rating and Score'!$G$94:$I$99,'OSM - Rating and Score'!$D$85:$D$90)*CG$6,2) -> 0.1 | CI45: =ROUND(VLOOKUP(AE45,'OSM - Rating and Score'!$C$8:$D$13,2,0)*CI$6,2) -> 0.4 | CK45: =ROUND(VLOOKUP(AG45,'OSM - Rating and Score'!$C$8:$D$13,2,0)*CK$6,2) -> 0.04 | CM45: 0 | CO45: =ROUND(VLOOKUP(AK45,'OSM - Rating and Score'!$C$8:$D$13,2,0)*CO$6,2) -> 0.28 | CQ45: =ROUND(VLOOKUP(AM45,'OSM - Rating and Score'!$C$47:$D$52,2,0)*CQ$6,2) -> 0.2 | CS45: =ROUND(VLOOKUP(AO45,'OSM - Rating and Score'!$C$47:$D$52,2,0)*CS$6,2) -> 0.15 | CU45: =ROUND(VLOOKUP(AQ45,'OSM - Rating and Score'!$C$47:$D$52,2,0)*CU$6,2) -> 0.15 | CW45: =ROUND(VLOOKUP(AS45,'OSM - Rating and Score'!$C$47:$D$52,2,0)*CW$6,2) -> 0.21 | CY45: =ROUND(VLOOKUP(AU45,'OSM - Rating and Score'!$C$65:$D$70,2,0)*CY$6,2) -> 0.15 | DA45: =ROUND(VLOOKUP(AW45,'OSM - Rating and Score'!$C$8:$D$13,2,0)*DA$6,2) -> 0 | DC45: =ROUND(VLOOKUP(AY45,'OSM - Rating and Score'!$C$75:$D$80,2,0)*DC$6,2) -> 0.2
C47: 21 | E47: blood Bank | I47: High | K47: Low | O47: High Barriers | Q47: Low Fit | S47: Limited Readiness | U47: Major New Team | W47: 250 | Y47: 5 | AA47: 0.25 | AC47: =ROUND(Y47*(1+AA47)^5,0) -> 15 | AE47: Medium | AG47: Minimal | AK47: High | AM47: Easy | AO47: Moderate | AQ47: Moderate | AS47: Moderate | AU47: Moderate | AW47: Medium | AY47: Medium | BA47: =IF(COUNTA(AY47,AW47,AU47,AS47,AQ47,AO47,AM47,AK47,AI47,AG47,AE47,AC47,AA47,Y47,W47,U47,S47,Q47,O47,K47,I47)=21,"✓","✗") -> ✗ | BC47: =IFERROR(SUM(BM47:DC47),"") -> 2.87 | BE47: =IFERROR(LOOKUP(BC47,'OSM - Rating and Score'!$G$103:$I$108,'OSM - Rating and Score'!$C$103:$C$108),"") -> Moderate | BM47: =ROUND(VLOOKUP(I47,'OSM - Rating and Score'!$C$8:$D$13,2,0)*BM$6,2) -> 0 | BO47: =ROUND(VLOOKUP(K47,'OSM - Rating and Score'!$C$8:$D$13,2,0)*BO$6,2) -> 0.1 | BS47: =ROUND(VLOOKUP(O47,'OSM - Rating and Score'!$C$17:$D$22,2,0)*BS$6,2) -> 0.1 | BU47: =ROUND(VLOOKUP(Q47,'OSM - Rating and Score'!$C$56:$D$61,2,0)*BU$6,2) -> 0.14 | BW47: =ROUND(VLOOKUP(S47,'OSM - Rating and Score'!$C$26:$D$31,2,0)*BW$6,2) -> 0.1 | BY47: =ROUND(VLOOKUP(U47,'OSM - Rating and Score'!$C$35:$D$40,2,0)*BY$6,2) -> 0.14 | CC47: =ROUND(LOOKUP(Y47,'OSM - Rating and Score'!$G$85:$I$90,'OSM - Rating and Score'!$D$85:$D$90)*CC$6,2) -> 0.3 | CE47: =ROUND(LOOKUP(AA47,'OSM - Rating and Score'!$G$113:$I$118,'OSM - Rating and Score'!$D$113:$D$118)*CE$6,2) -> 0.16 | CG47: =ROUND(LOOKUP(AC47,'OSM - Rating and Score'!$G$94:$I$99,'OSM - Rating and Score'!$D$85:$D$90)*CG$6,2) -> 0.2 | CI47: =ROUND(VLOOKUP(AE47,'OSM - Rating and Score'!$C$8:$D$13,2,0)*CI$6,2) -> 0.3 | CK47: =ROUND(VLOOKUP(AG47,'OSM - Rating and Score'!$C$8:$D$13,2,0)*CK$6,2) -> 0.04 | CM47: 0 | CO47: =ROUND(VLOOKUP(AK47,'OSM - Rating and Score'!$C$8:$D$13,2,0)*CO$6,2) -> 0.28 | CQ47: =ROUND(VLOOKUP(AM47,'OSM - Rating and Score'!$C$47:$D$52,2,0)*CQ$6,2) -> 0.2 | CS47: =ROUND(VLOOKUP(AO47,'OSM - Rating and Score'!$C$47:$D$52,2,0)*CS$6,2) -> 0.15 | CU47: =ROUND(VLOOKUP(AQ47,'OSM - Rating and Score'!$C$47:$D$52,2,0)*CU$6,2) -> 0.15 | CW47: =ROUND(VLOOKUP(AS47,'OSM - Rating and Score'!$C$47:$D$52,2,0)*CW$6,2) -> 0.21 | CY47: =ROUND(VLOOKUP(AU47,'OSM - Rating and Score'!$C$65:$D$70,2,0)*CY$6,2) -> 0.15 | DA47: =ROUND(VLOOKUP(AW47,'OSM - Rating and Score'!$C$8:$D$13,2,0)*DA$6,2) -> 0 | DC47: =ROUND(VLOOKUP(AY47,'OSM - Rating and Score'!$C$75:$D$80,2,0)*DC$6,2) -> 0.15
C49: 22 | E49: Equipment | G49: Monitors-Government | I49: High | K49: Very High | O49: Medium Barriers | Q49: Strong Fit | S49: Ready | U49: Some New Staff | W49: 150 | Y49: 10 | AA49: 0.2 | AC49: =ROUND(Y49*(1+AA49)^5,0) -> 25 | AE49: Medium | AG49: Minimal | AK49: Medium | AM49: Moderate | AO49: Moderate | AQ49: Easy | AS49: Moderate | AU49: Low Complex | AW49: Minimal | AY49: Medium | BA49: =IF(COUNTA(AY49,AW49,AU49,AS49,AQ49,AO49,AM49,AK49,AI49,AG49,AE49,AC49,AA49,Y49,W49,U49,S49,Q49,O49,K49,I49)=21,"✓","✗") -> ✗ | BC49: =IFERROR(SUM(BM49:DC49),"") -> 3.46 | BE49: =IFERROR(LOOKUP(BC49,'OSM - Rating and Score'!$G$103:$I$108,'OSM - Rating and Score'!$C$103:$C$108),"") -> Moderate | BG49: hold | BM49: =ROUND(VLOOKUP(I49,'OSM - Rating and Score'!$C$8:$D$13,2,0)*BM$6,2) -> 0 | BO49: =ROUND(VLOOKUP(K49,'OSM - Rating and Score'!$C$8:$D$13,2,0)*BO$6,2) -> 0.25 | BS49: =ROUND(VLOOKUP(O49,'OSM - Rating and Score'!$C$17:$D$22,2,0)*BS$6,2) -> 0.15 | BU49: =ROUND(VLOOKUP(Q49,'OSM - Rating and Score'!$C$56:$D$61,2,0)*BU$6,2) -> 0.28 | BW49: =ROUND(VLOOKUP(S49,'OSM - Rating and Score'!$C$26:$D$31,2,0)*BW$6,2) -> 0.2 | BY49: =ROUND(VLOOKUP(U49,'OSM - Rating and Score'!$C$35:$D$40,2,0)*BY$6,2) -> 0.21 | CC49: =ROUND(LOOKUP(Y49,'OSM - Rating and Score'!$G$85:$I$90,'OSM - Rating and Score'!$D$85:$D$90)*CC$6,2) -> 0.3 | CE49: =ROUND(LOOKUP(AA49,'OSM - Rating and Score'!$G$113:$I$118,'OSM - Rating and Score'!$D$113:$D$118)*CE$6,2) -> 0.16 | CG49: =ROUND(LOOKUP(AC49,'OSM - Rating and Score'!$G$94:$I$99,'OSM - Rating and Score'!$D$85:$D$90)*CG$6,2) -> 0.3 | CI49: =ROUND(VLOOKUP(AE49,'OSM - Rating and Score'!$C$8:$D$13,2,0)*CI$6,2) -> 0.3 | CK49: =ROUND(VLOOKUP(AG49,'OSM - Rating and Score'!$C$8:$D$13,2,0)*CK$6,2) -> 0.04 | CM49: 0 | CO49: =ROUND(VLOOKUP(AK49,'OSM - Rating and Score'!$C$8:$D$13,2,0)*CO$6,2) -> 0.21 | CQ49: =ROUND(VLOOKUP(AM49,'OSM - Rating and Score'!$C$47:$D$52,2,0)*CQ$6,2) -> 0.15 | CS49: =ROUND(VLOOKUP(AO49,'OSM - Rating and Score'!$C$47:$D$52,2,0)*CS$6,2) -> 0.15 | CU49: =ROUND(VLOOKUP(AQ49,'OSM - Rating and Score'!$C$47:$D$52,2,0)*CU$6,2) -> 0.2 | CW49: =ROUND(VLOOKUP(AS49,'OSM - Rating and Score'!$C$47:$D$52,2,0)*CW$6,2) -> 0.21 | CY49: =ROUND(VLOOKUP(AU49,'OSM - Rating and Score'!$C$65:$D$70,2,0)*CY$6,2) -> 0.2 | DA49: =ROUND(VLOOKUP(AW49,'OSM - Rating and Score'!$C$8:$D$13,2,0)*DA$6,2) -> 0 | DC49: =ROUND(VLOOKUP(AY49,'OSM - Rating and Score'!$C$75:$D$80,2,0)*DC$6,2) -> 0.15
